Workbook

Sheet Results Analysis
B2: True Positives
B3: = Detected correctly by ESCOX, also included in manual annotation
B4: Threshold | C4: 0.5 | D4: 0.55 | E4: 0.6 | F4: 0.65
B5: Absolute counts | C5: 19 | D5: 16 | E5: 11 | F5: 4
B7: False Positives
B8: = Detected by ESCOX, not included in manual annotation
B9: Threshold | C9: 0.5 | D9: 0.55 | E9: 0.6 | F9: 0.65
B10: Absolute counts | C10: 13 | D10: 7 | E10: 5 | F10: 2
B12: False Negatives
B13: = Not detected by ESCOX, but included in manual annotation
B14: Threshold | C14: 0.5 | D14: 0.55 | E14: 0.6 | F14: 0.65
B15: Absolute counts | C15: 7 | D15: 10 | E15: 15 | F15: 22
B17: Precision
B18: Threshold | C18: 0.5 | D18: 0.55 | E18: 0.6 | F18: 0.65
B19: Precision | C19: =C5/(C5+C10) -> 0.59375 | D19: =D5/(D5+D10) -> 0.69565217 | E19: =E5/(E5+E10) -> 0.6875 | F19: =F5/(F5+F10) -> 0.66666667
B21: Recall
B22: Threshold | C22: 0.5 | D22: 0.55 | E22: 0.6 | F22: 0.65
B23: Recall | C23: =C5/(C5+C15) -> 0.73076923 | D23: =D5/(D5+D15) -> 0.61538462 | E23: =E5/(E5+E15) -> 0.42307692 | F23: =F5/(F5+F15) -> 0.15384615
B25: F1
B26: Threshold | C26: 0.5 | D26: 0.55 | E26: 0.6 | F26: 0.65
B27: F1 | C27: =2*(C19*C23)/(C19+C23) -> 0.65517241 | D27: =2*(D19*D23)/(D19+D23) -> 0.65306122 | E27: =2*(E19*E23)/(E19+E23) -> 0.52380952 | F27: =2*(F19*F23)/(F19+F23) -> 0.25

Sheet Manual Reference An. Broad
A1: Module Title | B1: ESCO Skill URI | C1: ESCO Skill | D1: 0.5 detected | E1: 0.55 detected | F1: 0.6 detected | G1: 0.65 detected | H1: check if in ESCO_skills_allowed_data_domain | I1: broad skill uri | J1: broad skill name
A2: Introduction to Data Science | B2: http://data.europa.eu/esco/skill/edebd83d-35f6-4ed5-a940-6c203d178c01 | C2: data science | D2: Yes | E2: No | F2: No | G2: No | H2: =VLOOKUP(B2,data_skills!A:C,2,FALSE) -> data science | I2: =VLOOKUP(B2,'broaderSkills wo groups'!B:F,4,FALSE) -> #N/A
A3: Introduction to Data Science | B3: http://data.europa.eu/esco/skill/97bd1c21-66b2-4b7e-ad0f-e3cda590e378 | C3: data analytics | D3: Yes | E3: Yes | F3: Yes | G3: Yes | H3: =VLOOKUP(B3,data_skills!A:C,2,FALSE) -> data analytics | I3: =VLOOKUP(B3,'broaderSkills wo groups'!B:F,4,FALSE) -> #N/A
A4: Introduction to Data Science | B4: http://data.europa.eu/esco/skill/7ee4c2ea-b349-4bd2-81a3-ec31475d4833 | C4: statistics | D4: No | E4: No | F4: No | G4: No | H4: =VLOOKUP(B4,data_skills!A:C,2,FALSE) -> statistics | I4: =VLOOKUP(B4,'broaderSkills wo groups'!B:F,4,FALSE) -> #N/A
A5: Introduction to Data Science | B5: http://data.europa.eu/esco/skill/3a2d5b45-56e4-4f5a-a55a-4a4a65afdc43 | C5: machine learning | D5: No | E5: No | F5: No | G5: No | H5: =VLOOKUP(B5,data_skills!A:C,2,FALSE) -> machine learning | I5: =VLOOKUP(B5,'broaderSkills wo groups'!B:F,4,FALSE) -> http://data.europa.eu/esco/skill/e465a154-93f7-4973-9ce1-31659fe16dd2
A6: Introduction to Programming with Python | B6: http://data.europa.eu/esco/skill/ccd0a1d9-afda-43d9-b901-96344886e14d | C6: Python (computer programming) | D6: Yes | E6: Yes | F6: No | G6: No | H6: =VLOOKUP(B6,data_skills!A:C,2,FALSE) -> Python (computer programming) | I6: =VLOOKUP(B6,'broaderSkills wo groups'!B:F,4,FALSE) -> http://data.europa.eu/esco/skill/21d2f96d-35f7-4e3f-9745-c533d2dd6e97
A7: Introduction to Programming with Python | B7: http://data.europa.eu/esco/skill/2522a6ce-3202-4ac8-9f5b-b9cb5a3a83a1 | C7: debug software | D7: No | E7: No | F7: No | G7: No | H7: =VLOOKUP(B7,data_skills!A:C,2,FALSE) -> debug software | I7: =VLOOKUP(B7,'broaderSkills wo groups'!B:F,4,FALSE) -> #N/A
A8: Introduction to Programming with Python | B8: http://data.europa.eu/esco/skill/0c15aa34-6977-4da7-b1f0-2ba6a582ef1b | C8: monitor logging operations | D8: Yes | E8: Yes | F8: Yes | G8: No | H8: =VLOOKUP(B8,data_skills!A:C,2,FALSE) -> #N/A | I8: =VLOOKUP(B8,'broaderSkills wo groups'!B:F,4,FALSE) -> #N/A
A9: Introduction to Programming with Python | B9: http://data.europa.eu/esco/skill/797a4416-0b8d-44f3-8fcd-eb10bd0be6b4 | C9: develop software prototype | D9: No | E9: No | F9: No | G9: No | H9: =VLOOKUP(B9,data_skills!A:C,2,FALSE) -> develop software prototype | I9: =VLOOKUP(B9,'broaderSkills wo groups'!B:F,4,FALSE) -> #N/A
A10: Introduction to Academic Work for IT and Technology | B10: http://data.europa.eu/esco/skill/7a34b3d9-bd3b-4f4e-a0f6-f97439901cb7 | C10: apply scientific methods | D10: Yes | E10: Yes | F10: No | G10: No | H10: =VLOOKUP(B10,data_skills!A:C,2,FALSE) -> apply scientific methods | I10: =VLOOKUP(B10,'broaderSkills wo groups'!B:F,4,FALSE) -> #N/A
A11: Introduction to Academic Work for IT and Technology | B11: http://data.europa.eu/esco/skill/57b7804d-048b-4293-b8ac-a105d0468883 | C11: source criticism | D11: Yes | E11: Yes | F11: No | G11: No | H11: =VLOOKUP(B11,data_skills!A:C,2,FALSE) -> #N/A | I11: =VLOOKUP(B11,'broaderSkills wo groups'!B:F,4,FALSE) -> #N/A
A12: Database Modeling and Database Systems | B12: http://data.europa.eu/esco/skill/43ae58b9-5e56-4524-b45a-b422777a0576 | C12: database | D12: Yes | E12: Yes | F12: Yes | G12: Yes | H12: =VLOOKUP(B12,data_skills!A:C,2,FALSE) -> database | I12: =VLOOKUP(B12,'broaderSkills wo groups'!B:F,4,FALSE) -> #N/A
A13: Database Modeling and Database Systems | B13: http://data.europa.eu/esco/skill/598de5b0-5b58-4ea7-8058-a4bc4d18c742 | C13: SQL | D13: Yes | E13: Yes | F13: Yes | G13: No | H13: =VLOOKUP(B13,data_skills!A:C,2,FALSE) -> SQL | I13: =VLOOKUP(B13,'broaderSkills wo groups'!B:F,4,FALSE) -> http://data.europa.eu/esco/skill/9cf681c7-89ec-470c-b651-7fe03786f586
... A30: Exploratory Data Analysis and Visualization | B30: http://data.europa.eu/esco/skill/ccd0a1d9-afda-43d9-b901-96344886e14d | C30: Python (computer programming) | D30: No | E30: No | F30: No | G30: No | H30: =VLOOKUP(B30,data_skills!A:C,2,FALSE) -> Python (computer programming) | I30: =VLOOKUP(B30,'broaderSkills wo groups'!B:F,4,FALSE) -> http://data.europa.eu/esco/skill/21d2f96d-35f7-4e3f-9745-c533d2dd6e97

Sheet Manual Reference Annotation
A1: Module Title | B1: ESCO Skill URI | C1: ESCO Skill | D1: 0.5 detected | E1: 0.55 detected | F1: 0.6 detected | G1: 0.65 detected | H1: check if in ESCO_skills_allowed_data_domain
A2: Introduction to Data Science | B2: http://data.europa.eu/esco/skill/edebd83d-35f6-4ed5-a940-6c203d178c01 | C2: data science | D2: Yes | E2: No | F2: No | G2: No | H2: =VLOOKUP(B2,data_skills!A:C,2,FALSE) -> data science
A3: Introduction to Data Science | B3: http://data.europa.eu/esco/skill/97bd1c21-66b2-4b7e-ad0f-e3cda590e378 | C3: data analytics | D3: Yes | E3: Yes | F3: Yes | G3: Yes | H3: =VLOOKUP(B3,data_skills!A:C,2,FALSE) -> data analytics
A4: Introduction to Data Science | B4: http://data.europa.eu/esco/skill/7ee4c2ea-b349-4bd2-81a3-ec31475d4833 | C4: statistics | D4: No | E4: No | F4: No | G4: No | H4: =VLOOKUP(B4,data_skills!A:C,2,FALSE) -> statistics
A5: Introduction to Data Science | B5: http://data.europa.eu/esco/skill/3a2d5b45-56e4-4f5a-a55a-4a4a65afdc43 | C5: machine learning | D5: No | E5: No | F5: No | G5: No | H5: =VLOOKUP(B5,data_skills!A:C,2,FALSE) -> machine learning
A6: Introduction to Programming with Python | B6: http://data.europa.eu/esco/skill/ccd0a1d9-afda-43d9-b901-96344886e14d | C6: Python (computer programming) | D6: Yes | E6: Yes | F6: No | G6: No | H6: =VLOOKUP(B6,data_skills!A:C,2,FALSE) -> Python (computer programming)
A7: Introduction to Programming with Python | B7: http://data.europa.eu/esco/skill/2522a6ce-3202-4ac8-9f5b-b9cb5a3a83a1 | C7: debug software | D7: No | E7: No | F7: No | G7: No | H7: =VLOOKUP(B7,data_skills!A:C,2,FALSE) -> debug software
A8: Introduction to Programming with Python | B8: http://data.europa.eu/esco/skill/0c15aa34-6977-4da7-b1f0-2ba6a582ef1b | C8: monitor logging operations | D8: Yes | E8: Yes | F8: Yes | G8: No | H8: =VLOOKUP(B8,data_skills!A:C,2,FALSE) -> #N/A
A9: Introduction to Programming with Python | B9: http://data.europa.eu/esco/skill/797a4416-0b8d-44f3-8fcd-eb10bd0be6b4 | C9: develop software prototype | D9: No | E9: No | F9: No | G9: No | H9: =VLOOKUP(B9,data_skills!A:C,2,FALSE) -> develop software prototype
A10: Introduction to Academic Work for IT and Technology | B10: http://data.europa.eu/esco/skill/7a34b3d9-bd3b-4f4e-a0f6-f97439901cb7 | C10: apply scientific methods | D10: Yes | E10: Yes | F10: No | G10: No | H10: =VLOOKUP(B10,data_skills!A:C,2,FALSE) -> apply scientific methods
A11: Introduction to Academic Work for IT and Technology | B11: http://data.europa.eu/esco/skill/57b7804d-048b-4293-b8ac-a105d0468883 | C11: source criticism | D11: Yes | E11: Yes | F11: No | G11: No | H11: =VLOOKUP(B11,data_skills!A:C,2,FALSE) -> #N/A
A12: Database Modeling and Database Systems | B12: http://data.europa.eu/esco/skill/43ae58b9-5e56-4524-b45a-b422777a0576 | C12: database | D12: Yes | E12: Yes | F12: Yes | G12: Yes | H12: =VLOOKUP(B12,data_skills!A:C,2,FALSE) -> database
A13: Database Modeling and Database Systems | B13: http://data.europa.eu/esco/skill/598de5b0-5b58-4ea7-8058-a4bc4d18c742 | C13: SQL | D13: Yes | E13: Yes | F13: Yes | G13: No | H13: =VLOOKUP(B13,data_skills!A:C,2,FALSE) -> SQL
... A30: Exploratory Data Analysis and Visualization | B30: http://data.europa.eu/esco/skill/ccd0a1d9-afda-43d9-b901-96344886e14d | C30: Python (computer programming) | D30: No | E30: No | F30: No | G30: No | H30: =VLOOKUP(B30,data_skills!A:C,2,FALSE) -> Python (computer programming)

Sheet ESCOX thresholds results
A1: Module Code | B1: Module Title | C1: URI | D1: Threshold | E1: VLookupManualRefAnnotation | F1: SkillName | G1: Correctly detected | H1: check if in ESCO_skills_allowed_data_domain | I1: broaderSKillName
A2: DLBDSIDS-01 | B2: Introduction to Data Science | C2: http://data.europa.eu/esco/skill/0d6714c6-720e-4985-9791-5ab85d28da79 | D2: 0.5 | E2: =E9=VLOOKUP(C2,'Manual Reference Annotation'!B$2:B$5,1,FALSE) -> #N/A | F2: =VLOOKUP(E2,'Manual Reference Annotation'!B:C,2,FALSE) -> #N/A | G2: =IF(ISNA(E2),FALSE,TRUE) -> FALSE | H2: =VLOOKUP(C2,data_skills!A:B,1,FALSE) -> http://data.europa.eu/esco/skill/0d6714c6-720e-4985-9791-5ab85d28da79 | I2: =VLOOKUP(C2,'broaderSkills wo groups'!B:F,5,FALSE) -> use data processing techniques
A3: DLBDSIDS-01 | B3: Introduction to Data Science | C3: http://data.europa.eu/esco/skill/97bd1c21-66b2-4b7e-ad0f-e3cda590e378 | D3: 0.5 | E3: =VLOOKUP(C3,'Manual Reference Annotation'!B$2:B$5,1,FALSE) -> http://data.europa.eu/esco/skill/97bd1c21-66b2-4b7e-ad0f-e3cda590e378 | F3: =VLOOKUP(E3,'Manual Reference Annotation'!B:C,2,FALSE) -> data analytics | G3: =IF(ISNA(E3),FALSE,TRUE) -> TRUE | H3: =VLOOKUP(C3,data_skills!A:B,1,FALSE) -> http://data.europa.eu/esco/skill/97bd1c21-66b2-4b7e-ad0f-e3cda590e378 | I3: =VLOOKUP(C3,'broaderSkills wo groups'!B:F,5,FALSE) -> #N/A
A4: DLBDSIDS-01 | B4: Introduction to Data Science | C4: http://data.europa.eu/esco/skill/edebd83d-35f6-4ed5-a940-6c203d178c01 | D4: 0.5 | E4: =VLOOKUP(C4,'Manual Reference Annotation'!B$2:B$5,1,FALSE) -> http://data.europa.eu/esco/skill/edebd83d-35f6-4ed5-a940-6c203d178c01 | F4: =VLOOKUP(E4,'Manual Reference Annotation'!B:C,2,FALSE) -> data science | G4: =IF(ISNA(E4),FALSE,TRUE) -> TRUE | H4: =VLOOKUP(C4,data_skills!A:B,1,FALSE) -> http://data.europa.eu/esco/skill/edebd83d-35f6-4ed5-a940-6c203d178c01 | I4: =VLOOKUP(C4,'broaderSkills wo groups'!B:F,5,FALSE) -> #N/A
A5: DLBDSIDS-01 | B5: Introduction to Data Science | C5: http://data.europa.eu/esco/skill/97bd1c21-66b2-4b7e-ad0f-e3cda590e378 | D5: 0.55 | E5: =VLOOKUP(C5,'Manual Reference Annotation'!B$2:B$5,1,FALSE) -> http://data.europa.eu/esco/skill/97bd1c21-66b2-4b7e-ad0f-e3cda590e378 | F5: =VLOOKUP(E5,'Manual Reference Annotation'!B:C,2,FALSE) -> data analytics | G5: =IF(ISNA(E5),FALSE,TRUE) -> TRUE | H5: =VLOOKUP(C5,data_skills!A:B,1,FALSE) -> http://data.europa.eu/esco/skill/97bd1c21-66b2-4b7e-ad0f-e3cda590e378 | I5: =VLOOKUP(C5,'broaderSkills wo groups'!B:F,5,FALSE) -> #N/A
A6: DLBDSIDS-01 | B6: Introduction to Data Science | C6: http://data.europa.eu/esco/skill/edebd83d-35f6-4ed5-a940-6c203d178c01 | D6: 0.55 | E6: =VLOOKUP(C6,'Manual Reference Annotation'!B$2:B$5,1,FALSE) -> http://data.europa.eu/esco/skill/edebd83d-35f6-4ed5-a940-6c203d178c01 | F6: =VLOOKUP(E6,'Manual Reference Annotation'!B:C,2,FALSE) -> data science | G6: =IF(ISNA(E6),FALSE,TRUE) -> TRUE | H6: =VLOOKUP(C6,data_skills!A:B,1,FALSE) -> http://data.europa.eu/esco/skill/edebd83d-35f6-4ed5-a940-6c203d178c01 | I6: =VLOOKUP(C6,'broaderSkills wo groups'!B:F,5,FALSE) -> #N/A
A7: DLBDSIDS-01 | B7: Introduction to Data Science | C7: http://data.europa.eu/esco/skill/97bd1c21-66b2-4b7e-ad0f-e3cda590e378 | D7: 0.6 | E7: =VLOOKUP(C7,'Manual Reference Annotation'!B$2:B$5,1,FALSE) -> http://data.europa.eu/esco/skill/97bd1c21-66b2-4b7e-ad0f-e3cda590e378 | F7: =VLOOKUP(E7,'Manual Reference Annotation'!B:C,2,FALSE) -> data analytics | G7: =IF(ISNA(E7),FALSE,TRUE) -> TRUE | H7: =VLOOKUP(C7,data_skills!A:B,1,FALSE) -> http://data.europa.eu/esco/skill/97bd1c21-66b2-4b7e-ad0f-e3cda590e378 | I7: =VLOOKUP(C7,'broaderSkills wo groups'!B:F,5,FALSE) -> #N/A
A8: DLBDSIDS-01 | B8: Introduction to Data Science | C8: http://data.europa.eu/esco/skill/edebd83d-35f6-4ed5-a940-6c203d178c01 | D8: 0.6 | E8: =VLOOKUP(C8,'Manual Reference Annotation'!B$2:B$5,1,FALSE) -> http://data.europa.eu/esco/skill/edebd83d-35f6-4ed5-a940-6c203d178c01 | F8: =VLOOKUP(E8,'Manual Reference Annotation'!B:C,2,FALSE) -> data science | G8: =IF(ISNA(E8),FALSE,TRUE) -> TRUE | H8: =VLOOKUP(C8,data_skills!A:B,1,FALSE) -> http://data.europa.eu/esco/skill/edebd83d-35f6-4ed5-a940-6c203d178c01 | I8: =VLOOKUP(C8,'broaderSkills wo groups'!B:F,5,FALSE) -> #N/A
A9: DLBDSIPWP | B9: Introduction to Programming with Python | C9: http://data.europa.eu/esco/skill/0c15aa34-6977-4da7-b1f0-2ba6a582ef1b | D9: 0.5 | E9: =VLOOKUP(C9,'Manual Reference Annotation'!B$6:B$9,1,FALSE) -> http://data.europa.eu/esco/skill/0c15aa34-6977-4da7-b1f0-2ba6a582ef1b | F9: =VLOOKUP(E9,'Manual Reference Annotation'!B:C,2,FALSE) -> monitor logging operations | G9: =IF(ISNA(E9),FALSE,TRUE) -> TRUE | H9: =VLOOKUP(C9,data_skills!A:B,1,FALSE) -> #N/A | I9: =VLOOKUP(C9,'broaderSkills wo groups'!B:F,5,FALSE) -> #N/A
A10: DLBDSIPWP | B10: Introduction to Programming with Python | C10: http://data.europa.eu/esco/skill/ccd0a1d9-afda-43d9-b901-96344886e14d | D10: 0.5 | E10: =VLOOKUP(C10,'Manual Reference Annotation'!B$6:B$9,1,FALSE) -> http://data.europa.eu/esco/skill/ccd0a1d9-afda-43d9-b901-96344886e14d | F10: =VLOOKUP(E10,'Manual Reference Annotation'!B:C,2,FALSE) -> Python (computer programming) | G10: =IF(ISNA(E10),FALSE,TRUE) -> TRUE | H10: =VLOOKUP(C10,data_skills!A:B,1,FALSE) -> http://data.europa.eu/esco/skill/ccd0a1d9-afda-43d9-b901-96344886e14d | I10: =VLOOKUP(C10,'broaderSkills wo groups'!B:F,5,FALSE) -> computer programming
A11: DLBDSIPWP | B11: Introduction to Programming with Python | C11: http://data.europa.eu/esco/skill/d0245e61-204f-48ca-911b-45e564732682 | D11: 0.5 | E11: =VLOOKUP(C11,'Manual Reference Annotation'!B$6:B$9,1,FALSE) -> #N/A | F11: =VLOOKUP(E11,'Manual Reference Annotation'!B:C,2,FALSE) -> #N/A | G11: =IF(ISNA(E11),FALSE,TRUE) -> FALSE | H11: =VLOOKUP(C11,data_skills!A:B,1,FALSE) -> #N/A | I11: =VLOOKUP(C11,'broaderSkills wo groups'!B:F,5,FALSE) -> #N/A
A12: DLBDSIPWP | B12: Introduction to Programming with Python | C12: http://data.europa.eu/esco/skill/edebd83d-35f6-4ed5-a940-6c203d178c01 | D12: 0.5 | E12: =VLOOKUP(C12,'Manual Reference Annotation'!B$6:B$9,1,FALSE) -> #N/A | F12: =VLOOKUP(E12,'Manual Reference Annotation'!B:C,2,FALSE) -> #N/A | G12: =IF(ISNA(E12),FALSE,TRUE) -> FALSE | H12: =VLOOKUP(C12,data_skills!A:B,1,FALSE) -> http://data.europa.eu/esco/skill/edebd83d-35f6-4ed5-a940-6c203d178c01 | I12: =VLOOKUP(C12,'broaderSkills wo groups'!B:F,5,FALSE) -> #N/A
A13: DLBDSIPWP | B13: Introduction to Programming with Python | C13: http://data.europa.eu/esco/skill/0c15aa34-6977-4da7-b1f0-2ba6a582ef1b | D13: 0.55 | E13: =VLOOKUP(C13,'Manual Reference Annotation'!B$6:B$9,1,FALSE) -> http://data.europa.eu/esco/skill/0c15aa34-6977-4da7-b1f0-2ba6a582ef1b | F13: =VLOOKUP(E13,'Manual Reference Annotation'!B:C,2,FALSE) -> monitor logging operations | G13: =IF(ISNA(E13),FALSE,TRUE) -> TRUE | H13: =VLOOKUP(C13,data_skills!A:B,1,FALSE) -> #N/A | I13: =VLOOKUP(C13,'broaderSkills wo groups'!B:F,5,FALSE) -> #N/A
A14: DLBDSIPWP | B14: Introduction to Programming with Python | C14: http://data.europa.eu/esco/skill/ccd0a1d9-afda-43d9-b901-96344886e14d | D14: 0.55 | E14: =VLOOKUP(C14,'Manual Reference Annotation'!B$6:B$9,1,FALSE) -> http://data.europa.eu/esco/skill/ccd0a1d9-afda-43d9-b901-96344886e14d | F14: =VLOOKUP(E14,'Manual Reference Annotation'!B:C,2,FALSE) -> Python (computer programming) | G14: =IF(ISNA(E14),FALSE,TRUE) -> TRUE | H14: =VLOOKUP(C14,data_skills!A:B,1,FALSE) -> http://data.europa.eu/esco/skill/ccd0a1d9-afda-43d9-b901-96344886e14d | I14: =VLOOKUP(C14,'broaderSkills wo groups'!B:F,5,FALSE) -> computer programming
A15: DLBDSIPWP | B15: Introduction to Programming with Python | C15: http://data.europa.eu/esco/skill/edebd83d-35f6-4ed5-a940-6c203d178c01 | D15: 0.55 | E15: =VLOOKUP(C15,'Manual Reference Annotation'!B$6:B$9,1,FALSE) -> #N/A | F15: =VLOOKUP(E15,'Manual Reference Annotation'!B:C,2,FALSE) -> #N/A | G15: =IF(ISNA(E15),FALSE,TRUE) -> FALSE | H15: =VLOOKUP(C15,data_skills!A:B,1,FALSE) -> http://data.europa.eu/esco/skill/edebd83d-35f6-4ed5-a940-6c203d178c01 | I15: =VLOOKUP(C15,'broaderSkills wo groups'!B:F,5,FALSE) -> #N/A
A16: DLBDSIPWP | B16: Introduction to Programming with Python | C16: http://data.europa.eu/esco/skill/0c15aa34-6977-4da7-b1f0-2ba6a582ef1b | D16: 0.6 | E16: =VLOOKUP(C16,'Manual Reference Annotation'!B$6:B$9,1,FALSE) -> http://data.europa.eu/esco/skill/0c15aa34-6977-4da7-b1f0-2ba6a582ef1b | F16: =VLOOKUP(E16,'Manual Reference Annotation'!B:C,2,FALSE) -> monitor logging operations | G16: =IF(ISNA(E16),FALSE,TRUE) -> TRUE | H16: =VLOOKUP(C16,data_skills!A:B,1,FALSE) -> #N/A | I16: =VLOOKUP(C16,'broaderSkills wo groups'!B:F,5,FALSE) -> #N/A
A17: DLBDSIPWP | B17: Introduction to Programming with Python | C17: http://data.europa.eu/esco/skill/edebd83d-35f6-4ed5-a940-6c203d178c01 | D17: 0.6 | E17: =VLOOKUP(C17,'Manual Reference Annotation'!B$6:B$9,1,FALSE) -> #N/A | F17: =VLOOKUP(E17,'Manual Reference Annotation'!B:C,2,FALSE) -> #N/A | G17: =IF(ISNA(E17),FALSE,TRUE) -> FALSE | H17: =VLOOKUP(C17,data_skills!A:B,1,FALSE) -> http://data.europa.eu/esco/skill/edebd83d-35f6-4ed5-a940-6c203d178c01 | I17: =VLOOKUP(C17,'broaderSkills wo groups'!B:F,5,FALSE) -> #N/A
A18: DLBIAWITT | B18: Introduction to Academic Work for IT and Technology | C18: http://data.europa.eu/esco/skill/00b9a3aa-7070-4bb5-8020-f228a97cf42f | D18: 0.5 | E18: =VLOOKUP(C18,'Manual Reference Annotation'!B$10:B$11,1,FALSE) -> #N/A | F18: =VLOOKUP(E18,'Manual Reference Annotation'!B:C,2,FALSE) -> #N/A | G18: =IF(ISNA(E18),FALSE,TRUE) -> FALSE | H18: =VLOOKUP(C18,data_skills!A:B,1,FALSE) -> http://data.europa.eu/esco/skill/00b9a3aa-7070-4bb5-8020-f228a97cf42f | I18: =VLOOKUP(C18,'broaderSkills wo groups'!B:F,5,FALSE) -> #N/A
A19: DLBIAWITT | B19: Introduction to Academic Work for IT and Technology | C19: http://data.europa.eu/esco/skill/02e22093-3436-46a8-8dc5-b041bc4800cc | D19: 0.5 | E19: =VLOOKUP(C19,'Manual Reference Annotation'!B$10:B$11,1,FALSE) -> #N/A | F19: =VLOOKUP(E19,'Manual Reference Annotation'!B:C,2,FALSE) -> #N/A | G19: =IF(ISNA(E19),FALSE,TRUE) -> FALSE | H19: =VLOOKUP(C19,data_skills!A:B,1,FALSE) -> #N/A | I19: =VLOOKUP(C19,'broaderSkills wo groups'!B:F,5,FALSE) -> #N/A
A20: DLBIAWITT | B20: Introduction to Academic Work for IT and Technology | C20: http://data.europa.eu/esco/skill/055192dc-f16c-4855-835d-19cac6ff20aa | D20: 0.5 | E20: =VLOOKUP(C20,'Manual Reference Annotation'!B$10:B$11,1,FALSE) -> #N/A | F20: =VLOOKUP(E20,'Manual Reference Annotation'!B:C,2,FALSE) -> #N/A | G20: =IF(ISNA(E20),FALSE,TRUE) -> FALSE | H20: =VLOOKUP(C20,data_skills!A:B,1,FALSE) -> http://data.europa.eu/esco/skill/055192dc-f16c-4855-835d-19cac6ff20aa | I20: =VLOOKUP(C20,'broaderSkills wo groups'!B:F,5,FALSE) -> #N/A
A21: DLBIAWITT | B21: Introduction to Academic Work for IT and Technology | C21: http://data.europa.eu/esco/skill/57b7804d-048b-4293-b8ac-a105d0468883 | D21: 0.5 | E21: =VLOOKUP(C21,'Manual Reference Annotation'!B$10:B$11,1,FALSE) -> http://data.europa.eu/esco/skill/57b7804d-048b-4293-b8ac-a105d0468883 | F21: =VLOOKUP(E21,'Manual Reference Annotation'!B:C,2,FALSE) -> source criticism | G21: =IF(ISNA(E21),FALSE,TRUE) -> TRUE | H21: =VLOOKUP(C21,data_skills!A:B,1,FALSE) -> #N/A | I21: =VLOOKUP(C21,'broaderSkills wo groups'!B:F,5,FALSE) -> #N/A
A22: DLBIAWITT | B22: Introduction to Academic Work for IT and Technology | C22: http://data.europa.eu/esco/skill/72f9d741-7696-43d2-bccb-d46f9463eecb | D22: 0.5 | E22: =VLOOKUP(C22,'Manual Reference Annotation'!B$10:B$11,1,FALSE) -> #N/A | F22: =VLOOKUP(E22,'Manual Reference Annotation'!B:C,2,FALSE) -> #N/A | G22: =IF(ISNA(E22),FALSE,TRUE) -> FALSE | H22: =VLOOKUP(C22,data_skills!A:B,1,FALSE) -> #N/A | I22: =VLOOKUP(C22,'broaderSkills wo groups'!B:F,5,FALSE) -> #N/A
A23: DLBIAWITT | B23: Introduction to Academic Work for IT and Technology | C23: http://data.europa.eu/esco/skill/7a34b3d9-bd3b-4f4e-a0f6-f97439901cb7 | D23: 0.5 | E23: =VLOOKUP(C23,'Manual Reference Annotation'!B$10:B$11,1,FALSE) -> http://data.europa.eu/esco/skill/7a34b3d9-bd3b-4f4e-a0f6-f97439901cb7 | F23: =VLOOKUP(E23,'Manual Reference Annotation'!B:C,2,FALSE) -> apply scientific methods | G23: =IF(ISNA(E23),FALSE,TRUE) -> TRUE | H23: =VLOOKUP(C23,data_skills!A:B,1,FALSE) -> http://data.europa.eu/esco/skill/7a34b3d9-bd3b-4f4e-a0f6-f97439901cb7 | I23: =VLOOKUP(C23,'broaderSkills wo groups'!B:F,5,FALSE) -> #N/A
A24: DLBIAWITT | B24: Introduction to Academic Work for IT and Technology | C24: http://data.europa.eu/esco/skill/81a2db2c-7e55-44d0-9cd9-74c25147d7cd | D24: 0.5 | E24: =VLOOKUP(C24,'Manual Reference Annotation'!B$10:B$11,1,FALSE) -> #N/A | F24: =VLOOKUP(E24,'Manual Reference Annotation'!B:C,2,FALSE) -> #N/A | G24: =IF(ISNA(E24),FALSE,TRUE) -> FALSE | H24: =VLOOKUP(C24,data_skills!A:B,1,FALSE) -> #N/A | I24: =VLOOKUP(C24,'broaderSkills wo groups'!B:F,5,FALSE) -> evaluate data, information and digital content
A25: DLBIAWITT | B25: Introduction to Academic Work for IT and Technology | C25: http://data.europa.eu/esco/skill/ddc3119d-1d6e-4324-9125-a3380d299ac5 | D25: 0.5 | E25: =VLOOKUP(C25,'Manual Reference Annotation'!B$10:B$11,1,FALSE) -> #N/A | F25: =VLOOKUP(E25,'Manual Reference Annotation'!B:C,2,FALSE) -> #N/A | G25: =IF(ISNA(E25),FALSE,TRUE) -> FALSE | H25: =VLOOKUP(C25,data_skills!A:B,1,FALSE) -> http://data.europa.eu/esco/skill/ddc3119d-1d6e-4324-9125-a3380d299ac5 | I25: =VLOOKUP(C25,'broaderSkills wo groups'!B:F,5,FALSE) -> #N/A
A26: DLBIAWITT | B26: Introduction to Academic Work for IT and Technology | C26: http://data.europa.eu/esco/skill/02e22093-3436-46a8-8dc5-b041bc4800cc | D26: 0.55 | E26: =VLOOKUP(C26,'Manual Reference Annotation'!B$10:B$11,1,FALSE) -> #N/A | F26: =VLOOKUP(E26,'Manual Reference Annotation'!B:C,2,FALSE) -> #N/A | G26: =IF(ISNA(E26),FALSE,TRUE) -> FALSE | H26: =VLOOKUP(C26,data_skills!A:B,1,FALSE) -> #N/A | I26: =VLOOKUP(C26,'broaderSkills wo groups'!B:F,5,FALSE) -> #N/A
A27: DLBIAWITT | B27: Introduction to Academic Work for IT and Technology | C27: http://data.europa.eu/esco/skill/055192dc-f16c-4855-835d-19cac6ff20aa | D27: 0.55 | E27: =VLOOKUP(C27,'Manual Reference Annotation'!B$10:B$11,1,FALSE) -> #N/A | F27: =VLOOKUP(E27,'Manual Reference Annotation'!B:C,2,FALSE) -> #N/A | G27: =IF(ISNA(E27),FALSE,TRUE) -> FALSE | H27: =VLOOKUP(C27,data_skills!A:B,1,FALSE) -> http://data.europa.eu/esco/skill/055192dc-f16c-4855-835d-19cac6ff20aa | I27: =VLOOKUP(C27,'broaderSkills wo groups'!B:F,5,FALSE) -> #N/A
A28: DLBIAWITT | B28: Introduction to Academic Work for IT and Technology | C28: http://data.europa.eu/esco/skill/57b7804d-048b-4293-b8ac-a105d0468883 | D28: 0.55 | E28: =VLOOKUP(C28,'Manual Reference Annotation'!B$10:B$11,1,FALSE) -> http://data.europa.eu/esco/skill/57b7804d-048b-4293-b8ac-a105d0468883 | F28: =VLOOKUP(E28,'Manual Reference Annotation'!B:C,2,FALSE) -> source criticism | G28: =IF(ISNA(E28),FALSE,TRUE) -> TRUE | H28: =VLOOKUP(C28,data_skills!A:B,1,FALSE) -> #N/A | I28: =VLOOKUP(C28,'broaderSkills wo groups'!B:F,5,FALSE) -> #N/A
A29: DLBIAWITT | B29: Introduction to Academic Work for IT and Technology | C29: http://data.europa.eu/esco/skill/72f9d741-7696-43d2-bccb-d46f9463eecb | D29: 0.55 | E29: =VLOOKUP(C29,'Manual Reference Annotation'!B$10:B$11,1,FALSE) -> #N/A | F29: =VLOOKUP(E29,'Manual Reference Annotation'!B:C,2,FALSE) -> #N/A | G29: =IF(ISNA(E29),FALSE,TRUE) -> FALSE | H29: =VLOOKUP(C29,data_skills!A:B,1,FALSE) -> #N/A | I29: =VLOOKUP(C29,'broaderSkills wo groups'!B:F,5,FALSE) -> #N/A
... A31: DLBIAWITT | B31: Introduction to Academic Work for IT and Technology | C31: http://data.europa.eu/esco/skill/ddc3119d-1d6e-4324-9125-a3380d299ac5 | D31: 0.55 | E31: =VLOOKUP(C31,'Manual Reference Annotation'!B$10:B$11,1,FALSE) -> #N/A | F31: =VLOOKUP(E31,'Manual Reference Annotation'!B:C,2,FALSE) -> #N/A | G31: =IF(ISNA(E31),FALSE,TRUE) -> FALSE | H31: =VLOOKUP(C31,data_skills!A:B,1,FALSE) -> http://data.europa.eu/esco/skill/ddc3119d-1d6e-4324-9125-a3380d299ac5 | I31: =VLOOKUP(C31,'broaderSkills wo groups'!B:F,5,FALSE) -> #N/A
A32: DLBCSDMDS | B32: Database Modeling and Database Systems | C32: http://data.europa.eu/esco/skill/2f4f78ac-0246-4c59-907d-9fcb46f8fb77 | D32: 0.5 | E32: =VLOOKUP(C32,'Manual Reference Annotation'!B$12:B$18,1,FALSE) -> #N/A | F32: =VLOOKUP(E32,'Manual Reference Annotation'!B:C,2,FALSE) -> #N/A | G32: =IF(ISNA(E32),FALSE,TRUE) -> FALSE | H32: =VLOOKUP(C32,data_skills!A:B,1,FALSE) -> #N/A | I32: =VLOOKUP(C32,'broaderSkills wo groups'!B:F,5,FALSE) -> #N/A
A33: DLBCSDMDS | B33: Database Modeling and Database Systems | C33: http://data.europa.eu/esco/skill/3fc5a30d-d493-44ed-a2b5-ff9a50f84de3 | D33: 0.5 | E33: =VLOOKUP(C33,'Manual Reference Annotation'!B$12:B$18,1,FALSE) -> #N/A | F33: =VLOOKUP(E33,'Manual Reference Annotation'!B:C,2,FALSE) -> #N/A | G33: =IF(ISNA(E33),FALSE,TRUE) -> FALSE | H33: =VLOOKUP(C33,data_skills!A:B,1,FALSE) -> #N/A | I33: =VLOOKUP(C33,'broaderSkills wo groups'!B:F,5,FALSE) -> create solutions to problems
A34: DLBCSDMDS | B34: Database Modeling and Database Systems | C34: http://data.europa.eu/esco/skill/43ae58b9-5e56-4524-b45a-b422777a0576 | D34: 0.5 | E34: =VLOOKUP(C34,'Manual Reference Annotation'!B$12:B$18,1,FALSE) -> http://data.europa.eu/esco/skill/43ae58b9-5e56-4524-b45a-b422777a0576 | F34: =VLOOKUP(E34,'Manual Reference Annotation'!B:C,2,FALSE) -> database | G34: =IF(ISNA(E34),FALSE,TRUE) -> TRUE | H34: =VLOOKUP(C34,data_skills!A:B,1,FALSE) -> http://data.europa.eu/esco/skill/43ae58b9-5e56-4524-b45a-b422777a0576 | I34: =VLOOKUP(C34,'broaderSkills wo groups'!B:F,5,FALSE) -> #N/A
A35: DLBCSDMDS | B35: Database Modeling and Database Systems | C35: http://data.europa.eu/esco/skill/598de5b0-5b58-4ea7-8058-a4bc4d18c742 | D35: 0.5 | E35: =VLOOKUP(C35,'Manual Reference Annotation'!B$12:B$18,1,FALSE) -> http://data.europa.eu/esco/skill/598de5b0-5b58-4ea7-8058-a4bc4d18c742 | F35: =VLOOKUP(E35,'Manual Reference Annotation'!B:C,2,FALSE) -> SQL | G35: =IF(ISNA(E35),FALSE,TRUE) -> TRUE | H35: =VLOOKUP(C35,data_skills!A:B,1,FALSE) -> http://data.europa.eu/esco/skill/598de5b0-5b58-4ea7-8058-a4bc4d18c742 | I35: =VLOOKUP(C35,'broaderSkills wo groups'!B:F,5,FALSE) -> query languages
A36: DLBCSDMDS | B36: Database Modeling and Database Systems | C36: http://data.europa.eu/esco/skill/6c08403c-a5bb-4868-b8c2-b7d039c0e511 | D36: 0.5 | E36: =VLOOKUP(C36,'Manual Reference Annotation'!B$12:B$18,1,FALSE) -> http://data.europa.eu/esco/skill/6c08403c-a5bb-4868-b8c2-b7d039c0e511 | F36: =VLOOKUP(E36,'Manual Reference Annotation'!B:C,2,FALSE) -> design database scheme | G36: =IF(ISNA(E36),FALSE,TRUE) -> TRUE | H36: =VLOOKUP(C36,data_skills!A:B,1,FALSE) -> http://data.europa.eu/esco/skill/6c08403c-a5bb-4868-b8c2-b7d039c0e511 | I36: =VLOOKUP(C36,'broaderSkills wo groups'!B:F,5,FALSE) -> manage database
A37: DLBCSDMDS | B37: Database Modeling and Database Systems | C37: http://data.europa.eu/esco/skill/7369f779-4b71-4aab-8836-48b69c676eec | D37: 0.5 | E37: =VLOOKUP(C37,'Manual Reference Annotation'!B$12:B$18,1,FALSE) -> http://data.europa.eu/esco/skill/7369f779-4b71-4aab-8836-48b69c676eec | F37: =VLOOKUP(E37,'Manual Reference Annotation'!B:C,2,FALSE) -> operate relational database management system | G37: =IF(ISNA(E37),FALSE,TRUE) -> TRUE | H37: =VLOOKUP(C37,data_skills!A:B,1,FALSE) -> http://data.europa.eu/esco/skill/7369f779-4b71-4aab-8836-48b69c676eec | I37: =VLOOKUP(C37,'broaderSkills wo groups'!B:F,5,FALSE) -> #N/A
A38: DLBCSDMDS | B38: Database Modeling and Database Systems | C38: http://data.europa.eu/esco/skill/76ef6ed3-1658-4a1a-9593-204d799c6d0c | D38: 0.5 | E38: =VLOOKUP(C38,'Manual Reference Annotation'!B$12:B$18,1,FALSE) -> http://data.europa.eu/esco/skill/76ef6ed3-1658-4a1a-9593-204d799c6d0c | F38: =VLOOKUP(E38,'Manual Reference Annotation'!B:C,2,FALSE) -> NoSQL | G38: =IF(ISNA(E38),FALSE,TRUE) -> TRUE | H38: =VLOOKUP(C38,data_skills!A:B,1,FALSE) -> http://data.europa.eu/esco/skill/76ef6ed3-1658-4a1a-9593-204d799c6d0c | I38: =VLOOKUP(C38,'broaderSkills wo groups'!B:F,5,FALSE) -> database management systems
A39: DLBCSDMDS | B39: Database Modeling and Database Systems | C39: http://data.europa.eu/esco/skill/787cc6d2-d3e1-4e9a-8664-787ac7f1d15b | D39: 0.5 | E39: =VLOOKUP(C39,'Manual Reference Annotation'!B$12:B$18,1,FALSE) -> #N/A | F39: =VLOOKUP(E39,'Manual Reference Annotation'!B:C,2,FALSE) -> #N/A | G39: =IF(ISNA(E39),FALSE,TRUE) -> FALSE | H39: =VLOOKUP(C39,data_skills!A:B,1,FALSE) -> #N/A | I39: =VLOOKUP(C39,'broaderSkills wo groups'!B:F,5,FALSE) -> #N/A
A40: DLBCSDMDS | B40: Database Modeling and Database Systems | C40: http://data.europa.eu/esco/skill/84f58e3d-8669-4d83-8c1d-5dd1e73a654f | D40: 0.5 | E40: =VLOOKUP(C40,'Manual Reference Annotation'!B$12:B$18,1,FALSE) -> #N/A | F40: =VLOOKUP(E40,'Manual Reference Annotation'!B:C,2,FALSE) -> #N/A | G40: =IF(ISNA(E40),FALSE,TRUE) -> FALSE | H40: =VLOOKUP(C40,data_skills!A:B,1,FALSE) -> http://data.europa.eu/esco/skill/84f58e3d-8669-4d83-8c1d-5dd1e73a654f | I40: =VLOOKUP(C40,'broaderSkills wo groups'!B:F,5,FALSE) -> manage database
A41: DLBCSDMDS | B41: Database Modeling and Database Systems | C41: http://data.europa.eu/esco/skill/b87f6102-5bab-4e99-a5d8-11b6be1b99c2 | D41: 0.5 | E41: =VLOOKUP(C41,'Manual Reference Annotation'!B$12:B$18,1,FALSE) -> #N/A | F41: =VLOOKUP(E41,'Manual Reference Annotation'!B:C,2,FALSE) -> #N/A | G41: =IF(ISNA(E41),FALSE,TRUE) -> FALSE | H41: =VLOOKUP(C41,data_skills!A:B,1,FALSE) -> #N/A | I41: =VLOOKUP(C41,'broaderSkills wo groups'!B:F,5,FALSE) -> report facts
...

Sheet check if data related
A1: URI | B1: name | C1: data skill?
A2: http://data.europa.eu/esco/skill/0d6714c6-720e-4985-9791-5ab85d28da79 | B2: =VLOOKUP(A2,'ESCOX skill list'!A:D,4,FALSE) -> gather data | C2: =VLOOKUP(A2,data_skills!A:C,2,FALSE) -> gather data
A3: http://data.europa.eu/esco/skill/97bd1c21-66b2-4b7e-ad0f-e3cda590e378 | B3: =VLOOKUP(A3,'ESCOX skill list'!A:D,4,FALSE) -> data analytics | C3: =VLOOKUP(A3,data_skills!A:C,2,FALSE) -> data analytics
A4: http://data.europa.eu/esco/skill/edebd83d-35f6-4ed5-a940-6c203d178c01 | B4: =VLOOKUP(A4,'ESCOX skill list'!A:D,4,FALSE) -> data science | C4: =VLOOKUP(A4,data_skills!A:C,2,FALSE) -> data science
A5: http://data.europa.eu/esco/skill/0c15aa34-6977-4da7-b1f0-2ba6a582ef1b | B5: =VLOOKUP(A5,'ESCOX skill list'!A:D,4,FALSE) -> monitor logging operations | C5: =VLOOKUP(A5,data_skills!A:C,2,FALSE) -> #N/A
A6: http://data.europa.eu/esco/skill/ccd0a1d9-afda-43d9-b901-96344886e14d | B6: =VLOOKUP(A6,'ESCOX skill list'!A:D,4,FALSE) -> Python (computer programming) | C6: =VLOOKUP(A6,data_skills!A:C,2,FALSE) -> Python (computer programming)
A7: http://data.europa.eu/esco/skill/d0245e61-204f-48ca-911b-45e564732682 | B7: =VLOOKUP(A7,'ESCOX skill list'!A:D,4,FALSE) -> reconstruct program theory | C7: =VLOOKUP(A7,data_skills!A:C,2,FALSE) -> #N/A
A8: http://data.europa.eu/esco/skill/00b9a3aa-7070-4bb5-8020-f228a97cf42f | B8: =VLOOKUP(A8,'ESCOX skill list'!A:D,4,FALSE) -> draft scientific or academic papers and technical documentation | C8: =VLOOKUP(A8,data_skills!A:C,2,FALSE) -> draft scientific or academic papers and technical documentation
A9: http://data.europa.eu/esco/skill/02e22093-3436-46a8-8dc5-b041bc4800cc | B9: =VLOOKUP(A9,'ESCOX skill list'!A:D,4,FALSE) -> create model | C9: =VLOOKUP(A9,data_skills!A:C,2,FALSE) -> #N/A
A10: http://data.europa.eu/esco/skill/055192dc-f16c-4855-835d-19cac6ff20aa | B10: =VLOOKUP(A10,'ESCOX skill list'!A:D,4,FALSE) -> life sciences | C10: =VLOOKUP(A10,data_skills!A:C,2,FALSE) -> life sciences
A11: http://data.europa.eu/esco/skill/57b7804d-048b-4293-b8ac-a105d0468883 | B11: =VLOOKUP(A11,'ESCOX skill list'!A:D,4,FALSE) -> source criticism | C11: =VLOOKUP(A11,data_skills!A:C,2,FALSE) -> #N/A
A12: http://data.europa.eu/esco/skill/72f9d741-7696-43d2-bccb-d46f9463eecb | B12: =VLOOKUP(A12,'ESCOX skill list'!A:D,4,FALSE) -> classify books | C12: =VLOOKUP(A12,data_skills!A:C,2,FALSE) -> #N/A
A13: http://data.europa.eu/esco/skill/7a34b3d9-bd3b-4f4e-a0f6-f97439901cb7 | B13: =VLOOKUP(A13,'ESCOX skill list'!A:D,4,FALSE) -> apply scientific methods | C13: =VLOOKUP(A13,data_skills!A:C,2,FALSE) -> apply scientific methods
... A48: http://data.europa.eu/esco/skill/c3e36d05-8ae8-447f-bb2b-6f9409f85389 | B48: =VLOOKUP(A48,'ESCOX skill list'!A:D,4,FALSE) -> deliver visual presentation of data | C48: =VLOOKUP(A48,data_skills!A:C,2,FALSE) -> deliver visual presentation of data

Sheet broaderSkills wo groups
A1: conceptType | B1: conceptUri | C1: conceptLabel | D1: broaderType | E1: broaderUri | F1: broaderLabel
A2: KnowledgeSkillCompetence | B2: http://data.europa.eu/esco/skill/0005c151-5b5a-4a66-8aac-60e734beb1ab | C2: manage musical staff | D2: KnowledgeSkillCompetence | E2: http://data.europa.eu/esco/skill/75d8e5d9-bef3-418b-9011-01bff9f27207 | F2: lead others
A3: KnowledgeSkillCompetence | B3: http://data.europa.eu/esco/skill/0005c151-5b5a-4a66-8aac-60e734beb1ab | C3: manage musical staff | D3: KnowledgeSkillCompetence | E3: http://data.europa.eu/esco/skill/339ac029-066a-4985-9f9d-b3d7c8fea0bb | F3: manage staff
A4: KnowledgeSkillCompetence | B4: http://data.europa.eu/esco/skill/0007bdc2-dd15-4824-b7d6-416522c46f35 | C4: control compliance of railway vehicles regulations | D4: KnowledgeSkillCompetence | E4: http://data.europa.eu/esco/skill/23033c54-cc98-47dc-b972-4a8d1646754d | F4: inspect manufacture of rolling stock
A5: KnowledgeSkillCompetence | B5: http://data.europa.eu/esco/skill/000f1d3d-220f-4789-9c0a-cc742521fb02 | C5: Haskell | D5: KnowledgeSkillCompetence | E5: http://data.europa.eu/esco/skill/21d2f96d-35f7-4e3f-9745-c533d2dd6e97 | F5: computer programming
A6: KnowledgeSkillCompetence | B6: http://data.europa.eu/esco/skill/00298d97-3dc3-4086-a902-bce0a2fba831 | C6: lead police investigations | D6: KnowledgeSkillCompetence | E6: http://data.europa.eu/esco/skill/75d8e5d9-bef3-418b-9011-01bff9f27207 | F6: lead others
A7: KnowledgeSkillCompetence | B7: http://data.europa.eu/esco/skill/0037c821-2898-4919-b96e-7ed1cd89554c | C7: develop energy saving concepts | D7: KnowledgeSkillCompetence | E7: http://data.europa.eu/esco/skill/c2a0c52c-0b4b-4180-a918-92650ea3b458 | F7: think innovatively
A8: KnowledgeSkillCompetence | B8: http://data.europa.eu/esco/skill/004017c9-0337-4f5a-8077-798de9ef12e3 | C8: perform street interventions in social work | D8: KnowledgeSkillCompetence | E8: http://data.europa.eu/esco/skill/7d9bace0-63d0-4848-ac87-350a98082c12 | F8: participate actively in civic life
A9: KnowledgeSkillCompetence | B9: http://data.europa.eu/esco/skill/00506f28-e884-4496-800c-3477c67eb355 | C9: sport and exercise medicine | D9: KnowledgeSkillCompetence | E9: http://data.europa.eu/esco/skill/4d3f3068-9b6a-4f33-bfa5-a7b298bfd303 | F9: medical statistics
A10: KnowledgeSkillCompetence | B10: http://data.europa.eu/esco/skill/00506f28-e884-4496-800c-3477c67eb355 | C10: sport and exercise medicine | D10: KnowledgeSkillCompetence | E10: http://data.europa.eu/esco/skill/1236128d-9bb4-4d94-bc1e-40fd14824280 | F10: medicines
A11: KnowledgeSkillCompetence | B11: http://data.europa.eu/esco/skill/00831ebb-bac3-4bd1-8dae-2bca67be958d | C11: handle equipment while suspended | D11: KnowledgeSkillCompetence | E11: http://data.europa.eu/esco/skill/b6bdf202-524f-475d-b813-2aa9af005c37 | F11: move objects
A12: KnowledgeSkillCompetence | B12: http://data.europa.eu/esco/skill/0085e6bd-6829-4e8e-b302-842a7fe57ed9 | C12: teach housekeeping skills | D12: KnowledgeSkillCompetence | E12: http://data.europa.eu/esco/skill/699e7c26-6502-4e78-a823-3656ff5a5b8b | F12: instruct others
... A6461: KnowledgeSkillCompetence | B6461: http://data.europa.eu/esco/skill/fff5bc45-b506-4466-8977-4869079c1cb2 | C6461: coordinate construction activities | D6461: KnowledgeSkillCompetence | E6461: http://data.europa.eu/esco/skill/d7a67428-3afb-4bbd-932b-f6718ca489c5 | F6461: plan construction of houses

Sheet Module List to analyse
A1: Module Code | B1: Module Title | C1: Learning Outcomes | D1: Mandatory | E1: ESCOX skills (0.50) | F1: ESCOX n_skills (0.50) | G1: ESCOX skills (0.55) | H1: ESCOX n_skills (0.55) | I1: ESCOX skills (0.60) | J1: ESCOX n_skills (0.60) | K1: ESCOX skills (0.65) | L1: ESCOX n_skills (0.65)
A2: DLBDSIDS-01 | B2: Introduction to Data Science | C2: ▪ define data science and its relation to other fields. ▪ comprehend data science activities. ▪ recognize the origins of data and the challenges of working with data. ▪ understand how data science methods are integrated into business settings. ▪ grasp fundamental statistical concepts. ▪ appreciate the importance of machine learning in data science. | D2: Yes | E2: http://data.europa.eu/esco/skill/0d6714c6-720e-4985-9791-5ab85d28da79; http://data.europa.eu/esco/skill/97bd1c21-66b2-4b7e-ad0f-e3cda590e378; http://data.europa.eu/esco/skill/edebd83d-35f6-4ed5-a940-6c203d178c01 | F2: 3 | G2: http://data.europa.eu/esco/skill/97bd1c21-66b2-4b7e-ad0f-e3cda590e378; http://data.europa.eu/esco/skill/edebd83d-35f6-4ed5-a940-6c203d178c01 | H2: 2 | I2: http://data.europa.eu/esco/skill/97bd1c21-66b2-4b7e-ad0f-e3cda590e378; http://data.europa.eu/esco/skill/edebd83d-35f6-4ed5-a940-6c203d178c01 | J2: 2 | L2: 0
A3: DLBDSIPWP | B3: Introduction to Programming with Python | C3: ▪ use fundamental Python syntax. ▪ recollect common elementary data types. ▪ recognize foundational programming concepts and their realization in Python. ▪ understand error handling and logging. ▪ create working programs. ▪ list the most important libraries and packages for data science. | D3: Yes | E3: http://data.europa.eu/esco/skill/0c15aa34-6977-4da7-b1f0-2ba6a582ef1b; http://data.europa.eu/esco/skill/ccd0a1d9-afda-43d9-b901-96344886e14d; http://data.europa.eu/esco/skill/d0245e61-204f-48ca-911b-45e564732682; http://data.europa.eu/esco/skill/edebd83d-35f6-4ed5-a940-6c203d178c01 | F3: 4 | G3: http://data.europa.eu/esco/skill/0c15aa34-6977-4da7-b1f0-2ba6a582ef1b; http://data.europa.eu/esco/skill/ccd0a1d9-afda-43d9-b901-96344886e14d; http://data.europa.eu/esco/skill/edebd83d-35f6-4ed5-a940-6c203d178c01 | H3: 3 | I3: http://data.europa.eu/esco/skill/0c15aa34-6977-4da7-b1f0-2ba6a582ef1b; http://data.europa.eu/esco/skill/edebd83d-35f6-4ed5-a940-6c203d178c01 | J3: 2 | L3: 0
A4: DLBIAWITT | B4: Introduction to Academic Work for IT and Technology | C4: ▪ explain what science is and why science is needed (including in practice-based studies and professional practice). ▪ name and apply theories, methods, and models in IT and technology. ▪ find, analyze, and classify academic literature and types of sources. ▪ prepare academic papers independently. | D4: Yes | E4: http://data.europa.eu/esco/skill/00b9a3aa-7070-4bb5-8020-f228a97cf42f; http://data.europa.eu/esco/skill/02e22093-3436-46a8-8dc5-b041bc4800cc; http://data.europa.eu/esco/skill/055192dc-f16c-4855-835d-19cac6ff20aa; http://data.europa.eu/esco/skill/57b7804d-048b-4293-b8ac-a105d0468883; http://data.europa.eu/esco/skill/72f9d741-7696-43d2-bccb-d46f9463eecb; http://data.europa.eu/esco/skill/7a34b3d9-bd3b-4f4e-a0f6-f97439901cb7; http://data.europa.eu/esco/skill/81a2db2c-7e55-44d0-9cd9-74c25147d7cd; http://data.europa.eu/esco/skill/ddc3119d-1d6e-4324-9125-a3380d299ac5 | F4: 8 | G4: http://data.europa.eu/esco/skill/02e22093-3436-46a8-8dc5-b041bc4800cc; http://data.europa.eu/esco/skill/055192dc-f16c-4855-835d-19cac6ff20aa; http://data.europa.eu/esco/skill/57b7804d-048b-4293-b8ac-a105d0468883; http://data.europa.eu/esco/skill/72f9d741-7696-43d2-bccb-d46f9463eecb; http://data.europa.eu/esco/skill/7a34b3d9-bd3b-4f4e-a0f6-f97439901cb7; http://data.europa.eu/esco/skill/ddc3119d-1d6e-4324-9125-a3380d299ac5 | H4: 6 | J4: 0 | L4: 0
A5: DLBCSDMDS | B5: Database Modeling and Database Systems | C5: ▪ describe the basic concepts of the relational data model and distinguish them from each other. ▪ visually model data schemas. ▪ know SQL queries, read data from databases, change the data stock, and have experience in their use. ▪ design, create, and modify SQL queries and data schemas for SQL databases, and have experience using them. ▪ independently design database schemas and create database queries to solve concrete problems. ▪ know the most important NoSQL concepts and distinguish them from each other. | D5: Yes | E5: http://data.europa.eu/esco/skill/2f4f78ac-0246-4c59-907d-9fcb46f8fb77; http://data.europa.eu/esco/skill/3fc5a30d-d493-44ed-a2b5-ff9a50f84de3; http://data.europa.eu/esco/skill/43ae58b9-5e56-4524-b45a-b422777a0576; http://data.europa.eu/esco/skill/598de5b0-5b58-4ea7-8058-a4bc4d18c742; http://data.europa.eu/esco/skill/6c08403c-a5bb-4868-b8c2-b7d039c0e511; http://data.europa.eu/esco/skill/7369f779-4b71-4aab-8836-48b69c676eec; http://data.europa.eu/esco/skill/76ef6ed3-1658-4a1a-9593-204d799c6d0c; http://data.europa.eu/esco/skill/787cc6d2-d3e1-4e9a-8664-787ac7f1d15b; http://data.europa.eu/esco/skill/84f58e3d-8669-4d83-8c1d-5dd1e73a654f; http://data.europa.eu/esco/skill/b87f6102-5bab-4e99-a5d8-11b6be1b99c2; http://data.europa.eu/esco/skill/cb5cccc9-abe4-4b11-abe6-d27e5cd85fb1; http://data.europa.eu/esco/skill/fecf8a0d-62c4-4e71-9b03-0f4fc2ad7bf5 | F5: 12 | G5: http://data.europa.eu/esco/skill/43ae58b9-5e56-4524-b45a-b422777a0576; http://data.europa.eu/esco/skill/598de5b0-5b58-4ea7-8058-a4bc4d18c742; http://data.europa.eu/esco/skill/6c08403c-a5bb-4868-b8c2-b7d039c0e511; http://data.europa.eu/esco/skill/7369f779-4b71-4aab-8836-48b69c676eec; http://data.europa.eu/esco/skill/76ef6ed3-1658-4a1a-9593-204d799c6d0c; http://data.europa.eu/esco/skill/cb5cccc9-abe4-4b11-abe6-d27e5cd85fb1; http://data.europa.eu/esco/skill/fecf8a0d-62c4-4e71-9b03-0f4fc2ad7bf5 | H5: 7 | I5: http://data.europa.eu/esco/skill/43ae58b9-5e56-4524-b45a-b422777a0576; http://data.europa.eu/esco/skill/598de5b0-5b58-4ea7-8058-a4bc4d18c742; http://data.europa.eu/esco/skill/6c08403c-a5bb-4868-b8c2-b7d039c0e511; http://data.europa.eu/esco/skill/76ef6ed3-1658-4a1a-9593-204d799c6d0c; http://data.europa.eu/esco/skill/cb5cccc9-abe4-4b11-abe6-d27e5cd85fb1; http://data.europa.eu/esco/skill/fecf8a0d-62c4-4e71-9b03-0f4fc2ad7bf5 | J5: 6 | K5: http://data.europa.eu/esco/skill/43ae58b9-5e56-4524-b45a-b422777a0576; http://data.europa.eu/esco/skill/fecf8a0d-62c4-4e71-9b03-0f4fc2ad7bf5 | L5: 2
A6: DLBDSPBDM | B6: Project: Build a Data Mart in SQL | C6: ▪ transfer previously-acquired knowledge about database methods and approaches to practical use cases. ▪ design, architect, and implement a working data-mart solution. ▪ reason about design choices of and trade-offs between relevant implementation alternatives. ▪ critically evaluate said choices with respect to the stated design goal. ▪ describe and explain the resulting solution. | D6: Yes | E6: http://data.europa.eu/esco/skill/0d11711b-870f-4701-be93-fa175b6e4002; http://data.europa.eu/esco/skill/3ec2e4d6-7000-4905-bf1a-c5b1679416de; http://data.europa.eu/esco/skill/b87f6102-5bab-4e99-a5d8-11b6be1b99c2; http://data.europa.eu/esco/skill/bc5deb5a-5b54-4241-b52e-68389d9a1e92 | F6: 4 | G6: http://data.europa.eu/esco/skill/3ec2e4d6-7000-4905-bf1a-c5b1679416de | H6: 1 | J6: 0 | L6: 0
A7: DLBDSMLSL | B7: Machine Learning - Supervised Learning | C7: ▪ remember central notions and paradigms of machine learning. ▪ describe the key ideas of regression and pertaining regularization methods. ▪ know basic classification techniques. ▪ explain tree structured machine learning models. ▪ understand support vector machines and the related kernel approach. | D7: Yes | E7: http://data.europa.eu/esco/skill/3a2d5b45-56e4-4f5a-a55a-4a4a65afdc43; http://data.europa.eu/esco/skill/49812c2d-3a36-4be8-bd41-8c0be3db7c6d; http://data.europa.eu/esco/skill/9983816d-cc78-4d3f-9e3c-c7baa9ebc77a | F7: 3 | G7: http://data.europa.eu/esco/skill/3a2d5b45-56e4-4f5a-a55a-4a4a65afdc43 | H7: 1 | J7: 0 | L7: 0
A8: DLBCSEBI2 | B8: Project: Business Intelligence | C8: ▪ independently design a solution to a practical problem in the field of Business Intelligence in order to then implement a prototype and document the results. ▪ identify and explain typical problems and challenges in the design and practical implementation of small BI solutions. | D8: Yes | E8: http://data.europa.eu/esco/skill/143769cb-b61e-47d8-a61e-eedfbec1016c; http://data.europa.eu/esco/skill/75f650d0-9096-4b8f-bbd6-ad05ee3f6121; http://data.europa.eu/esco/skill/f9b52e2d-56a7-48ca-b04d-2fc6436fcd4f | F8: 3 | G8: http://data.europa.eu/esco/skill/143769cb-b61e-47d8-a61e-eedfbec1016c; http://data.europa.eu/esco/skill/75f650d0-9096-4b8f-bbd6-ad05ee3f6121 | H8: 2 | I8: http://data.europa.eu/esco/skill/143769cb-b61e-47d8-a61e-eedfbec1016c; http://data.europa.eu/esco/skill/75f650d0-9096-4b8f-bbd6-ad05ee3f6121 | J8: 2 | L8: 0
A9: DLBDSBDT | B9: Big Data Technologies | C9: ▪ name types and sources of data. ▪ understand text-based and binary data formats. ▪ analyze the requirements and constraints of distributed analysis systems. ▪ evaluate the applications of streaming frameworks. ▪ describe the motivation for NoSQL data stores and categorize pertaining established concepts. | D9: Yes | E9: http://data.europa.eu/esco/skill/46ec0033-3c71-415e-bcff-b065675ba2dc; http://data.europa.eu/esco/skill/76ef6ed3-1658-4a1a-9593-204d799c6d0c; http://data.europa.eu/esco/skill/83b493c8-4837-41e3-9800-cff1df06cf38; http://data.europa.eu/esco/skill/9a58cd26-58eb-4a1c-b1b6-64037fe9cfa1; http://data.europa.eu/esco/skill/a8797f21-1af0-4c5e-98ca-bf1442929363; http://data.europa.eu/esco/skill/e2d44a9b-f28c-489e-9861-b654b5ded507 | F9: 6 | G9: http://data.europa.eu/esco/skill/46ec0033-3c71-415e-bcff-b065675ba2dc; http://data.europa.eu/esco/skill/76ef6ed3-1658-4a1a-9593-204d799c6d0c; http://data.europa.eu/esco/skill/a8797f21-1af0-4c5e-98ca-bf1442929363; http://data.europa.eu/esco/skill/e2d44a9b-f28c-489e-9861-b654b5ded507 | H9: 4 | I9: http://data.europa.eu/esco/skill/46ec0033-3c71-415e-bcff-b065675ba2dc; http://data.europa.eu/esco/skill/76ef6ed3-1658-4a1a-9593-204d799c6d0c; http://data.europa.eu/esco/skill/a8797f21-1af0-4c5e-98ca-bf1442929363 | J9: 3 | K9: http://data.europa.eu/esco/skill/76ef6ed3-1658-4a1a-9593-204d799c6d0c; http://data.europa.eu/esco/skill/a8797f21-1af0-4c5e-98ca-bf1442929363 | L9: 2
A10: DLBDSCC | B10: Cloud Computing | C10: ▪ understand the fundamentals of cloud computing and cloud service models. ▪ recognize enabling technologies that underlie current cloud offerings. ▪ cite the principles of serverless computing. ▪ analyze characteristics of established cloud offerings. ▪ describe cloud options for data science and machine learning | D10: Yes | E10: http://data.europa.eu/esco/skill/0a52bed5-fd29-45fb-aba6-e32bccfda1c1; http://data.europa.eu/esco/skill/3a2d5b45-56e4-4f5a-a55a-4a4a65afdc43; http://data.europa.eu/esco/skill/83218cac-3599-417e-93d2-26013cdccd98; http://data.europa.eu/esco/skill/bd14968e-e409-45af-b362-3495ed7b10e0; http://data.europa.eu/esco/skill/edebd83d-35f6-4ed5-a940-6c203d178c01; http://data.europa.eu/esco/skill/f4cd7802-123a-4bd5-9bfa-bf915a04e969 | F10: 6 | G10: http://data.europa.eu/esco/skill/83218cac-3599-417e-93d2-26013cdccd98; http://data.europa.eu/esco/skill/edebd83d-35f6-4ed5-a940-6c203d178c01 | H10: 2 | I10: http://data.europa.eu/esco/skill/83218cac-3599-417e-93d2-26013cdccd98; http://data.europa.eu/esco/skill/edebd83d-35f6-4ed5-a940-6c203d178c01 | J10: 2 | K10: http://data.europa.eu/esco/skill/83218cac-3599-417e-93d2-26013cdccd98 | L10: 1
A11: DLBDSEDAV | B11: Exploratory Data Analysis and Visualization | C11: ▪ recognize foundational concepts of exploratory data analysis. ▪ cite principles of data visualization. ▪ identify well-established types of visualizations and their appropriate uses. ▪ describe visualization best practices. ▪ understand practical data visualization fundamentals in Python. ▪ use different approaches for effective visual communication of data science results. | D11: Yes | E11: http://data.europa.eu/esco/skill/348b74cd-49ce-4844-8bdf-ec188b497213; http://data.europa.eu/esco/skill/65e58886-bd1e-4c5b-8ca5-8d9b353c8aa1; http://data.europa.eu/esco/skill/c3e36d05-8ae8-447f-bb2b-6f9409f85389 | F11: 3 | G11: http://data.europa.eu/esco/skill/348b74cd-49ce-4844-8bdf-ec188b497213; http://data.europa.eu/esco/skill/65e58886-bd1e-4c5b-8ca5-8d9b353c8aa1; http://data.europa.eu/esco/skill/c3e36d05-8ae8-447f-bb2b-6f9409f85389 | H11: 3 | I11: http://data.europa.eu/esco/skill/348b74cd-49ce-4844-8bdf-ec188b497213; http://data.europa.eu/esco/skill/65e58886-bd1e-4c5b-8ca5-8d9b353c8aa1 | J11: 2 | L11: 0

Sheet All modules ESCOX thresholds
A1: Module Code | B1: Module Title | C1: Learning Outcomes | D1: Mandatory | E1: ESCOX skills (0.50) | F1: ESCOX n_skills (0.50) | G1: ESCOX skills (0.55) | H1: ESCOX n_skills (0.55) | I1: ESCOX skills (0.60) | J1: ESCOX n_skills (0.60) | K1: ESCOX skills (0.65) | L1: ESCOX n_skills (0.65)
A2: DLBDSIDS-01 | B2: Introduction to Data Science | C2: ▪ define data science and its relation to other fields. ▪ comprehend data science activities. ▪ recognize the origins of data and the challenges of working with data. ▪ understand how data science methods are integrated into business settings. ▪ grasp fundamental statistical concepts. ▪ appreciate the importance of machine learning in data science. | D2: Yes | E2: http://data.europa.eu/esco/skill/0d6714c6-720e-4985-9791-5ab85d28da79; http://data.europa.eu/esco/skill/97bd1c21-66b2-4b7e-ad0f-e3cda590e378; http://data.europa.eu/esco/skill/edebd83d-35f6-4ed5-a940-6c203d178c01 | F2: 3 | G2: http://data.europa.eu/esco/skill/97bd1c21-66b2-4b7e-ad0f-e3cda590e378; http://data.europa.eu/esco/skill/edebd83d-35f6-4ed5-a940-6c203d178c01 | H2: 2 | I2: http://data.europa.eu/esco/skill/97bd1c21-66b2-4b7e-ad0f-e3cda590e378; http://data.europa.eu/esco/skill/edebd83d-35f6-4ed5-a940-6c203d178c01 | J2: 2 | L2: 0
A3: DLBDSIPWP | B3: Introduction to Programming with Python | C3: ▪ use fundamental Python syntax. ▪ recollect common elementary data types. ▪ recognize foundational programming concepts and their realization in Python. ▪ understand error handling and logging. ▪ create working programs. ▪ list the most important libraries and packages for data science. | D3: Yes | E3: http://data.europa.eu/esco/skill/0c15aa34-6977-4da7-b1f0-2ba6a582ef1b; http://data.europa.eu/esco/skill/ccd0a1d9-afda-43d9-b901-96344886e14d; http://data.europa.eu/esco/skill/d0245e61-204f-48ca-911b-45e564732682; http://data.europa.eu/esco/skill/edebd83d-35f6-4ed5-a940-6c203d178c01 | F3: 4 | G3: http://data.europa.eu/esco/skill/0c15aa34-6977-4da7-b1f0-2ba6a582ef1b; http://data.europa.eu/esco/skill/ccd0a1d9-afda-43d9-b901-96344886e14d; http://data.europa.eu/esco/skill/edebd83d-35f6-4ed5-a940-6c203d178c01 | H3: 3 | I3: http://data.europa.eu/esco/skill/0c15aa34-6977-4da7-b1f0-2ba6a582ef1b; http://data.europa.eu/esco/skill/edebd83d-35f6-4ed5-a940-6c203d178c01 | J3: 2 | L3: 0
A4: DLBDSMFLA | B4: Mathematics: Linear Algebra | C4: ▪ explain fundamental notions in the domain of linear equation systems. ▪ exemplify properties of vectors and vector spaces. ▪ summarize characteristics of linear and affine mappings. ▪ identify important relations in analytical geometry. ▪ utilize different methods for matrix decomposition. | D4: Yes | E4: http://data.europa.eu/esco/skill/343de837-064c-4d69-8505-741f5a2296ed | F4: 1 | H4: 0 | J4: 0 | L4: 0
A5: DLBIAWITT | B5: Introduction to Academic Work for IT and Technology | C5: ▪ explain what science is and why science is needed (including in practice-based studies and professional practice). ▪ name and apply theories, methods, and models in IT and technology. ▪ find, analyze, and classify academic literature and types of sources. ▪ prepare academic papers independently. | D5: Yes | E5: http://data.europa.eu/esco/skill/00b9a3aa-7070-4bb5-8020-f228a97cf42f; http://data.europa.eu/esco/skill/02e22093-3436-46a8-8dc5-b041bc4800cc; http://data.europa.eu/esco/skill/055192dc-f16c-4855-835d-19cac6ff20aa; http://data.europa.eu/esco/skill/57b7804d-048b-4293-b8ac-a105d0468883; http://data.europa.eu/esco/skill/72f9d741-7696-43d2-bccb-d46f9463eecb; http://data.europa.eu/esco/skill/7a34b3d9-bd3b-4f4e-a0f6-f97439901cb7; http://data.europa.eu/esco/skill/81a2db2c-7e55-44d0-9cd9-74c25147d7cd; http://data.europa.eu/esco/skill/ddc3119d-1d6e-4324-9125-a3380d299ac5 | F5: 8 | G5: http://data.europa.eu/esco/skill/02e22093-3436-46a8-8dc5-b041bc4800cc; http://data.europa.eu/esco/skill/055192dc-f16c-4855-835d-19cac6ff20aa; http://data.europa.eu/esco/skill/57b7804d-048b-4293-b8ac-a105d0468883; http://data.europa.eu/esco/skill/72f9d741-7696-43d2-bccb-d46f9463eecb; http://data.europa.eu/esco/skill/7a34b3d9-bd3b-4f4e-a0f6-f97439901cb7; http://data.europa.eu/esco/skill/ddc3119d-1d6e-4324-9125-a3380d299ac5 | H5: 6 | J5: 0 | L5: 0
A6: DLBDSOOFPP | B6: Project: Object Oriented and Functional Programming with Python | C6: ▪ explain basic notions in object-oriented programming such as functions and classes. ▪ understand object-oriented programming concepts and their relation to software design and engineering. ▪ describe advanced function concepts in Python. ▪ recognize important ideas from functional programming. ▪ recall important libraries for functional programming in Python. | D6: Yes | E6: http://data.europa.eu/esco/skill/21d2f96d-35f7-4e3f-9745-c533d2dd6e97; http://data.europa.eu/esco/skill/3bddfd7c-ab6d-40c2-883d-5e97fb7640ba; http://data.europa.eu/esco/skill/5dd96c59-5955-474b-8cf5-e986a5b50f1a; http://data.europa.eu/esco/skill/ccd0a1d9-afda-43d9-b901-96344886e14d; http://data.europa.eu/esco/skill/d31fab87-2a7d-485c-b699-2901ca294b15 | F6: 5 | G6: http://data.europa.eu/esco/skill/21d2f96d-35f7-4e3f-9745-c533d2dd6e97; http://data.europa.eu/esco/skill/3bddfd7c-ab6d-40c2-883d-5e97fb7640ba; http://data.europa.eu/esco/skill/5dd96c59-5955-474b-8cf5-e986a5b50f1a; http://data.europa.eu/esco/skill/ccd0a1d9-afda-43d9-b901-96344886e14d; http://data.europa.eu/esco/skill/d31fab87-2a7d-485c-b699-2901ca294b15 | H6: 5 | I6: http://data.europa.eu/esco/skill/21d2f96d-35f7-4e3f-9745-c533d2dd6e97; http://data.europa.eu/esco/skill/3bddfd7c-ab6d-40c2-883d-5e97fb7640ba; http://data.europa.eu/esco/skill/d31fab87-2a7d-485c-b699-2901ca294b15 | J6: 3 | K6: http://data.europa.eu/esco/skill/d31fab87-2a7d-485c-b699-2901ca294b15 | L6: 1
A7: DLBDSMFC | B7: Mathematics: Analysis | C7: ▪ summarize the basic concepts of analysis. ▪ illustrate the terms "sequences" and "series". ▪ explain the concept of a function and determine the inverse function where possible. ▪ compute derivatives and integrals using the standard rules of differentiation and integration. ▪ explain the relationship between differentiation and integration. ▪ solve simple linear differential equations. | D7: Yes | E7: http://data.europa.eu/esco/skill/633a3637-2c6b-40ae-ac38-289eb2a62aa6 | F7: 1 | G7: http://data.europa.eu/esco/skill/633a3637-2c6b-40ae-ac38-289eb2a62aa6 | H7: 1 | J7: 0 | L7: 0
A8: DLBDSSPDS-01 | B8: Statistics: Probability and Descriptive Statistics | C8: ▪ define probability, random variable, and probability distribution. ▪ understand the concept of Bayesian statistics. ▪ grasp the definition of joint and marginal distributions. ▪ calculate expectation values and higher moments. ▪ comprehend important inequality equations and limit theorems. | D8: Yes | E8: http://data.europa.eu/esco/skill/b758675a-b03b-4e4b-897c-57ca14b1a3d0 | F8: 1 | G8: http://data.europa.eu/esco/skill/b758675a-b03b-4e4b-897c-57ca14b1a3d0 | H8: 1 | I8: http://data.europa.eu/esco/skill/b758675a-b03b-4e4b-897c-57ca14b1a3d0 | J8: 1 | L8: 0
A9: DLBCSDMDS | B9: Database Modeling and Database Systems | C9: ▪ describe the basic concepts of the relational data model and distinguish them from each other. ▪ visually model data schemas. ▪ know SQL queries, read data from databases, change the data stock, and have experience in their use. ▪ design, create, and modify SQL queries and data schemas for SQL databases, and have experience using them. ▪ independently design database schemas and create database queries to solve concrete problems. ▪ know the most important NoSQL concepts and distinguish them from each other. | D9: Yes | E9: http://data.europa.eu/esco/skill/2f4f78ac-0246-4c59-907d-9fcb46f8fb77; http://data.europa.eu/esco/skill/3fc5a30d-d493-44ed-a2b5-ff9a50f84de3; http://data.europa.eu/esco/skill/43ae58b9-5e56-4524-b45a-b422777a0576; http://data.europa.eu/esco/skill/598de5b0-5b58-4ea7-8058-a4bc4d18c742; http://data.europa.eu/esco/skill/6c08403c-a5bb-4868-b8c2-b7d039c0e511; http://data.europa.eu/esco/skill/7369f779-4b71-4aab-8836-48b69c676eec; http://data.europa.eu/esco/skill/76ef6ed3-1658-4a1a-9593-204d799c6d0c; http://data.europa.eu/esco/skill/787cc6d2-d3e1-4e9a-8664-787ac7f1d15b; http://data.europa.eu/esco/skill/84f58e3d-8669-4d83-8c1d-5dd1e73a654f; http://data.europa.eu/esco/skill/b87f6102-5bab-4e99-a5d8-11b6be1b99c2; http://data.europa.eu/esco/skill/cb5cccc9-abe4-4b11-abe6-d27e5cd85fb1; http://data.europa.eu/esco/skill/fecf8a0d-62c4-4e71-9b03-0f4fc2ad7bf5 | F9: 12 | G9: http://data.europa.eu/esco/skill/43ae58b9-5e56-4524-b45a-b422777a0576; http://data.europa.eu/esco/skill/598de5b0-5b58-4ea7-8058-a4bc4d18c742; http://data.europa.eu/esco/skill/6c08403c-a5bb-4868-b8c2-b7d039c0e511; http://data.europa.eu/esco/skill/7369f779-4b71-4aab-8836-48b69c676eec; http://data.europa.eu/esco/skill/76ef6ed3-1658-4a1a-9593-204d799c6d0c; http://data.europa.eu/esco/skill/cb5cccc9-abe4-4b11-abe6-d27e5cd85fb1; http://data.europa.eu/esco/skill/fecf8a0d-62c4-4e71-9b03-0f4fc2ad7bf5 | H9: 7 | I9: http://data.europa.eu/esco/skill/43ae58b9-5e56-4524-b45a-b422777a0576; http://data.europa.eu/esco/skill/598de5b0-5b58-4ea7-8058-a4bc4d18c742; http://data.europa.eu/esco/skill/6c08403c-a5bb-4868-b8c2-b7d039c0e511; http://data.europa.eu/esco/skill/76ef6ed3-1658-4a1a-9593-204d799c6d0c; http://data.europa.eu/esco/skill/cb5cccc9-abe4-4b11-abe6-d27e5cd85fb1; http://data.europa.eu/esco/skill/fecf8a0d-62c4-4e71-9b03-0f4fc2ad7bf5 | J9: 6 | K9: http://data.europa.eu/esco/skill/43ae58b9-5e56-4524-b45a-b422777a0576; http://data.europa.eu/esco/skill/fecf8a0d-62c4-4e71-9b03-0f4fc2ad7bf5 | L9: 2
